<?xml version="1.0"?>
<robot name="mobile_robot" xmlns:xacro="http://ros.org/wiki/xacro">

  <!-- Colors -->
  <material name="blue">
    <color rgba="0 0 0.8 1"/>
  </material>
  <material name="black">
    <color rgba="0 0 0 1"/>
  </material>
  <material name="white">
    <color rgba="1 1 1 1"/>
  </material>
  <material name="red">
    <color rgba="1 0 0 1"/>
  </material>

  <!-- Base Link -->
  <link name="base_footprint"/>

  <joint name="base_joint" type="fixed">
    <parent link="base_footprint"/>
    <child link="base_link"/>
    <origin xyz="0 0 0.01" rpy="0 0 0"/>
  </joint>

  <link name="base_link">
    <visual>
      <geometry>
        <box size="0.25 0.15 0.01"/>
      </geometry>
      <material name="blue"/>
    </visual>
    <collision>
      <geometry>
        <box size="0.25 0.15 0.01"/>
      </geometry>
    </collision>
    <inertial>
      <mass value="0.5"/>
      <origin xyz="0 0 0" rpy="0 0 0"/>
      <inertia ixx="0.00083" ixy="0" ixz="0" 
               iyy="0.00083" iyz="0" 
               izz="0.00083"/>
    </inertial>
  </link>

  <!-- Left Wheel -->
  <link name="left_wheel">
    <visual>
      <geometry>
        <cylinder length="0.01" radius="0.035"/>
      </geometry>
      <material name="black"/>
    </visual>
    <collision>
      <geometry>
        <cylinder length="0.01" radius="0.035"/>
      </geometry>
    </collision>
    <inertial>
      <mass value="0.1"/>
      <origin xyz="0 0 0" rpy="0 0 0"/>
      <inertia ixx="0.00004" ixy="0" ixz="0" 
               iyy="0.00004" iyz="0" 
               izz="0.00004"/>
    </inertial>
  </link>

  <joint name="left_wheel_joint" type="continuous">
    <parent link="base_link"/>
    <child link="left_wheel"/>
    <origin xyz="0.07 0.08 -0.03" rpy="-1.5707 0 0"/>
    <axis xyz=" 0 0 1"/>
  </joint>

  <!-- Right Wheel -->
  <link name="right_wheel">
    <visual>
      <geometry>
        <cylinder length="0.01" radius="0.035"/>
      </geometry>
      <material name="black"/>
    </visual>
    <collision>
      <geometry>
        <cylinder length="0.01" radius="0.035"/>
      </geometry>
    </collision>
    <inertial>
      <mass value="0.1"/>
      <origin xyz="0 0 0" rpy="0 0 0"/>
      <inertia ixx="0.00004" ixy="0" ixz="0" 
               iyy="0.00004" iyz="0" 
               izz="0.00004"/>
    </inertial>
  </link>

  <joint name="right_wheel_joint" type="continuous">
    <parent link="base_link"/>
    <child link="right_wheel"/>
    <origin xyz="0.07 -0.08 -0.03" rpy="-1.5707 0 0"/>
    <axis xyz="0 0 1"/>
  </joint>

  <!-- Left Caster Wheel -->
  <link name="left_caster">
    <visual>
      <geometry>
        <sphere radius="0.03"/>
      </geometry>
      <material name="black"/>
    </visual>
    <collision>
      <geometry>
        <sphere radius="0.03"/>
      </geometry>
    </collision>
    <inertial>
      <mass value="0.05"/>
      <origin xyz="0 0 0" rpy="0 0 0"/>
      <inertia ixx="0.00001" ixy="0" ixz="0" 
               iyy="0.00001" iyz="0" 
               izz="0.00001"/>
    </inertial>
  </link>

  <joint name="left_caster_joint" type="continuous">
    <parent link="base_link"/>
    <child link="left_caster"/>
    <origin xyz="-0.11 0.06 -0.03" rpy="-1.5707 0 0"/>
    <axis xyz ="0 0 1"/>
  </joint>

  <!-- Right Caster Wheel -->
  <link name="right_caster">
    <visual>
      <geometry>
        <sphere radius="0.03"/>
      </geometry>
      <material name="black"/>
    </visual>
    <collision>
      <geometry>
        <sphere radius="0.03"/>
      </geometry>
    </collision>
    <inertial>
      <mass value="0.05"/>
      <origin xyz="0 0 0" rpy="0 0 0"/>
      <inertia ixx="0.00001" ixy="0" ixz="0" 
               iyy="0.00001" iyz="0" 
               izz="0.00001"/>
    </inertial>
  </link>

  <joint name="right_caster_joint" type="continuous">
    <parent link="base_link"/>
    <child link="right_caster"/>
    <origin xyz="-0.11 -0.06 -0.03" rpy="-1.5707 0 0"/>
     <axis xyz=" 0 0 1"/>
  </joint>

  <!-- Top Box -->
  <link name="top_box">
    <visual>
      <geometry>
        <box size="0.05 0.05 0.03"/>
      </geometry>
      <material name="white"/>
    </visual>
    <collision>
      <geometry>
        <box size="0.05 0.05 0.03"/>
      </geometry>
    </collision>
    <inertial>
      <mass value="0.1"/>
      <origin xyz="0 0 0" rpy="0 0 0"/>
      <inertia ixx="0.00004" ixy="0" ixz="0" 
               iyy="0.00004" iyz="0" 
               izz="0.00004"/>
    </inertial>
  </link>

  <joint name="top_box_joint" type="fixed">
    <parent link="base_link"/>
    <child link="top_box"/>
    <origin xyz="0.05 0 0.025" rpy="0 0 0"/>
  </joint>

  <!-- LIDAR SETUP -->
  <link name="lidar_link">
    <collision>
      <origin xyz="0 0 0" rpy="0 0 0"/>
      <geometry>
        <cylinder radius="0.02" length="0.05"/>
      </geometry>
    </collision>
    <visual>
      <origin xyz="0 0 0" rpy="0 0 0"/>
      <geometry>
        <cylinder radius="0.02" length="0.05"/>
      </geometry>
      <material name="black"/>
    </visual>
    <inertial>
      <mass value="0.114" />
      <origin xyz="0 0 0" rpy="0 0 0"/>
      <inertia ixx="0.001" ixy="0" ixz="0" iyy="0.001" iyz="0" izz="0.001" />
    </inertial>
  </link>

  <joint name="lidar_joint" type="fixed">
    <parent link="top_box"/>
    <child link="lidar_link"/>
    <origin xyz="0.002 0 0.03" rpy="0 0 0"/>
  </joint>

  <!-- Camera -->
  <link name="camera_link">
    <visual>
      <geometry>
        <cylinder radius="0.015" length="0.031" />
      </geometry>
      <material name="red" />
    </visual>
    <collision>
      <geometry>
        <cylinder radius="0.002" length="0.031" />
      </geometry>
    </collision>
    <inertial>
      <mass value="0.1" />
      <inertia ixx="0.001" ixy="0" ixz="0" iyy="0.001" iyz="0" izz="0.001" />
    </inertial>
  </link>

  <joint name="camera_joint" type="fixed">
    <parent link="base_link" />
    <child link="camera_link" />
    <origin rpy="0 0 0" xyz="0.1 0 0.01" />
  </joint>

 
</robot>

